2018-09-24 15:54:53,573 root         INFO     Logger successfully initialised
2018-09-24 15:54:53,574 impresso_commons.path.path_s3 INFO     Start collecting key from s3 (not parallel)
2018-09-24 15:54:56,529 impresso_commons.path.path_s3 INFO     Start processing key.
2018-09-24 15:55:09,219 __main__     INFO     Dask cluster: <Client: scheduler='tcp://127.0.0.1:59643' processes=8 cores=8>
2018-09-24 15:55:09,232 __main__     INFO     Number of partitions: 101
2018-09-24 16:06:27,947 __main__     INFO     Compressing 101 JSON files into impresso_commons/data/rebuilt/GDL-1986.jsonl.bz2
2018-09-24 16:09:51,851 __main__     INFO     Removed temporary directory and files in impresso_commons/data/rebuilt/GDL-1986
2018-09-24 16:09:51,920 __main__     ERROR    Required parameter name not set
2018-09-24 16:09:51,920 __main__     ERROR    The upload of impresso_commons/data/rebuilt/GDL-1986.jsonl.bz2 failed with error Required parameter name not set
2018-09-24 16:09:51,920 impresso_commons.path.path_s3 INFO     Start collecting key from s3 (not parallel)
2018-09-24 16:09:55,015 impresso_commons.path.path_s3 INFO     Start processing key.
2018-09-24 16:10:08,791 asyncio      ERROR    Exception in callback BaseAsyncIOLoop._handle_events(155, 1)
handle: <Handle BaseAsyncIOLoop._handle_events(155, 1)>
Traceback (most recent call last):
  File "/Users/rromanello/.pyenv/versions/3.6.0/lib/python3.6/asyncio/events.py", line 126, in _run
    self._callback(*self._args)
  File "/Users/rromanello/.local/share/virtualenvs/impresso-pycommons-C3qoP0NT/lib/python3.6/site-packages/tornado/platform/asyncio.py", line 122, in _handle_events
    handler_func(fileobj, events)
  File "/Users/rromanello/.local/share/virtualenvs/impresso-pycommons-C3qoP0NT/lib/python3.6/site-packages/tornado/stack_context.py", line 300, in null_wrapper
    return fn(*args, **kwargs)
  File "/Users/rromanello/.local/share/virtualenvs/impresso-pycommons-C3qoP0NT/lib/python3.6/site-packages/tornado/netutil.py", line 249, in accept_handler
  File "/Users/rromanello/.pyenv/versions/3.6.0/lib/python3.6/socket.py", line 205, in accept
OSError: [Errno 24] Too many open files
2018-09-24 16:10:08,792 asyncio      ERROR    Exception in callback BaseAsyncIOLoop._handle_events(155, 1)
handle: <Handle BaseAsyncIOLoop._handle_events(155, 1)>
Traceback (most recent call last):
  File "/Users/rromanello/.pyenv/versions/3.6.0/lib/python3.6/asyncio/events.py", line 126, in _run
    self._callback(*self._args)
  File "/Users/rromanello/.local/share/virtualenvs/impresso-pycommons-C3qoP0NT/lib/python3.6/site-packages/tornado/platform/asyncio.py", line 122, in _handle_events
    handler_func(fileobj, events)
  File "/Users/rromanello/.local/share/virtualenvs/impresso-pycommons-C3qoP0NT/lib/python3.6/site-packages/tornado/stack_context.py", line 300, in null_wrapper
    return fn(*args, **kwargs)
  File "/Users/rromanello/.local/share/virtualenvs/impresso-pycommons-C3qoP0NT/lib/python3.6/site-packages/tornado/netutil.py", line 249, in accept_handler
  File "/Users/rromanello/.pyenv/versions/3.6.0/lib/python3.6/socket.py", line 205, in accept
OSError: [Errno 24] Too many open files
